<?xml version="1.0"?>
<robot xmlns:xacro="http://www.ros.org/wiki/xacro" name="rvd">


  <!-- Property Definitions -->
    <xacro:property name="robot_width" value="0.455"/>
    <xacro:property name="robot_length" value="0.573"/>
    <xacro:property name="robot_height" value="1.25"/>
    <xacro:property name="pi" value="3.1415"/>
    <xacro:property name="wheel_dia" value="0.175"/>
    <xacro:property name="small_wheel_dia" value="0.04"/>

    <link name="base_link">
        <!-- <visual>
            <origin xyz="0.0 0.0 0.0" rpy="${pi * 0.5} 0.0 0.0"/>
            <geometry>
                <cylinder radius="0.02" length="0.62"/>
            </geometry>
        </visual> -->
    </link>

  <!-- Material Definitions -->
    <material name="black">
        <color rgba="0.0 0.0 0.0 1.0"/>
    </material>
    <material name="white">
        <color rgba="1.0 1.0 1.0 1.0"/>
    </material>
    <material name="blue">
        <color rgba="0.0 0.0 1.0 1.0"/>
    </material>
    <material name="green">
        <color rgba="0.0 1.0 0.0 1.0"/>
    </material>
    <material name="roda">
        <color rgba="0.4 0.4313 0.40784 1.0"/>
    </material>

  <!-- Link Definitions -->
    <link name="body_link">
        <visual>
            <origin xyz="0.0 0.0 ${wheel_dia * 0.5}" rpy="0.0 0.0 0.0"/>
            <geometry>
            <mesh filename="package://my_robot_description/mesh/UpperBody.stl" scale="1 1 1"/>
            </geometry>
            <material name="black"/>
        </visual>
        <collision>
            <origin xyz="0.0 0.0 ${wheel_dia * 0.5}" rpy="0.0 0.0 0.0"/>
            <geometry>
            <mesh filename="package://my_robot_description/mesh/UpperBody.stl" scale="1 1 1"/>
            </geometry>
        </collision>
        <inertial>
            <origin xyz="0.0 0.0 ${wheel_dia * 0.5}" rpy="0.0 0.0 0.0"/>
            <mass value="5.0"/>
            <inertia ixx="1" ixy="0" ixz="0" iyy="1" iyz="0" izz="1"/>
        </inertial>
    </link>

    <link name="battery_link">
        <visual>
            <origin xyz="0.0 0.0 0.0" rpy="0.0 0.0 0.0"/>
            <geometry>
            <mesh filename="package://my_robot_description/mesh/Battery.stl" scale="1 1 1"/>
            </geometry>
            <material name="black"/>
        </visual>
        <collision>
            <origin xyz="0.0 0.0 0.0" rpy="0.0 0.0 0.0"/>
            <geometry>
            <mesh filename="package://my_robot_description/mesh/Battery.stl" scale="1 1 1"/>
            </geometry>
        </collision>
        <inertial>
            <origin xyz="0.0 0.0 0.0" rpy="0.0 0.0 0.0"/>
            <mass value="2.5"/>
            <inertia ixx="1" ixy="0" ixz="0" iyy="1" iyz="0" izz="1"/>
        </inertial>
    </link>

    <link name="right_wheel">
        <visual>
            <origin xyz="0.0 0 0" rpy="0.0 0.0 0"/>
            <geometry>
                <mesh filename="package://my_robot_description/meshes/wheel.stl" scale="1 1 1"/>
            </geometry>
            <material name="roda"/>
        </visual>
        <collision>
            <origin xyz="0.0 0 0" rpy="0.0 0.0 0"/>
            <geometry>
                <mesh filename="package://my_robot_description/meshes/wheel.stl" scale="1 1 1"/>
            </geometry>
        </collision>
        <inertial>
            <mass value="0.8"/>
            <origin xyz="0.0 0 0" rpy="0.0 0.0 0"/>
            <inertia ixx="0.001" ixy="0.0" ixz="0.0" iyy="0.001" iyz="0.0" izz="0.001"/>
        </inertial>
    </link>

    <link name="left_wheel">
        <visual>
            <origin xyz="0.0 0 0" rpy="0.0 0.0 0"/>
            <geometry>
                <mesh filename="package://my_robot_description/meshes/wheel.stl" scale="1 1 1"/>
            </geometry>
            <material name="roda"/>
        </visual>
        <collision>
            <origin xyz="0.0 0 0" rpy="0.0 0.0 0"/>
            <geometry>
                <mesh filename="package://my_robot_description/meshes/wheel.stl" scale="1 1 1"/>
            </geometry>
        </collision>
        <inertial>
            <mass value="0.8"/>
            <origin xyz="0.0 0 0" rpy="0.0 0.0 0"/>
            <inertia ixx="0.001" ixy="0.0" ixz="0.0" iyy="0.001" iyz="0.0" izz="0.001"/>
        </inertial>
    </link>

    <link name="small_wheel_left">
        <visual>
            <origin xyz="0.0 0 0" rpy="0.0 0.0 0"/>
            <geometry>
                <mesh filename="package://my_robot_description/meshes/small_wheel.stl" scale="1 1 1"/>
            </geometry>
            <material name="roda"/>
        </visual>
        <collision>
            <origin xyz="0.0 0 0" rpy="0.0 0.0 0"/>
            <geometry>
                <mesh filename="package://my_robot_description/meshes/small_wheel.stl" scale="1 1 1"/>
            </geometry>
        </collision>
        <inertial>
            <mass value="0.3"/>
            <origin xyz="0.0 0 0" rpy="0.0 0.0 0"/>
            <inertia ixx="0.001" ixy="0.0" ixz="0.0" iyy="0.001" iyz="0.0" izz="0.001"/>
        </inertial>
    </link>

    <link name="small_wheel_right">
        <visual>
            <origin xyz="0.0 0 0" rpy="0.0 0.0 0"/>
            <geometry>
                <mesh filename="package://my_robot_description/meshes/small_wheel.stl" scale="1 1 1"/>
            </geometry>
            <material name="roda"/>
        </visual>
        <collision>
            <origin xyz="0.0 0 0" rpy="0.0 0.0 0"/>
            <geometry>
                <mesh filename="package://my_robot_description/meshes/small_wheel.stl" scale="1 1 1"/>
            </geometry>
        </collision>
        <inertial>
            <mass value="0.3"/>
            <origin xyz="0.0 0 0" rpy="0.0 0.0 0"/>
            <inertia ixx="0.001" ixy="0.0" ixz="0.0" iyy="0.001" iyz="0.0" izz="0.001"/>
        </inertial>
    </link>

    <joint name="body_link_joint" type="fixed">
        <parent link="base_link"/>
        <child link="body_link"/>
        <origin xyz="0.0 0.0 0.0" rpy="0.0 0.0 0.0"/>
    </joint>

    <joint name="battery_joint" type="fixed">
        <parent link="body_link"/>
        <child link="battery_link"/>
        <origin xyz="0.0 0.0 ${(wheel_dia * 0.5)}" rpy="0.0 0.0 0.0"/>
    </joint>

    <joint name="right_wheel_joint" type="continuous">
        <parent link="body_link"/>
        <child link="right_wheel"/>
        <origin xyz="-0.06 0.16 ${wheel_dia * 0.5}" rpy="0.0 0.0 0"/>
        <axis xyz="0 1 0"/>
        <limit lower="-3.14" upper="3.14" effort="10" velocity="40"/>
    </joint>
    
    <joint name="left_wheel_jount" type="continuous">
        <parent link="body_link"/>
        <child link="left_wheel"/>
        <origin xyz="-0.06 -0.16 ${wheel_dia * 0.5}" rpy="0.0 0.0 0"/>
        <axis xyz="0 1 0"/>
        <limit lower="-3.14" upper="3.14" effort="10" velocity="40"/>
    </joint>

    <joint name="small_wheel_left_joint" type="continuous">
        <parent link="body_link"/>
        <child link="small_wheel_left"/>
        <origin xyz="0.17 -0.10 ${small_wheel_dia * 0.5}" rpy="0.0 0.0 0"/>
        <axis xyz="0 1 0"/>
        <limit lower="-3.14" upper="3.14" effort="10" velocity="40"/>
    </joint>

    <joint name="small_wheel_right_joint" type="continuous">
        <parent link="body_link"/>
        <child link="small_wheel_right"/>
        <origin xyz="0.17 0.10 ${small_wheel_dia * 0.5}" rpy="0.0 0.0 0"/>
        <axis xyz="0 1 0"/>
        <limit lower="-3.14" upper="3.14" effort="10" velocity="40"/>
    </joint>







<!-- RPLIDAR A2M8 -->
<link name="rplidar_link">
<visual>
    <origin xyz="0 0 0" rpy="0 0 0"/>
    <geometry>
    <cylinder length="0.03" radius="0.038"/>
    </geometry>
    <material name="black"/>
</visual>
<collision>
    <origin xyz="0 0 0" rpy="0 0 0"/>
    <geometry>
    <cylinder length="0.03" radius="0.038"/>
    </geometry>
</collision>
<inertial>
    <mass value="0.2"/>
    <origin xyz="0 0 0" rpy="0 0 0"/>
    <inertia ixx="1e-5" ixy="0" ixz="0" iyy="1e-5" iyz="0" izz="1e-5"/>
</inertial>
</link>

<joint name="rplidar_joint" type="fixed">
<parent link="base_link"/>
<child link="rplidar_link"/>
<origin xyz="0.0 0.0 0.3" rpy="0 0 0"/>
</joint>

<gazebo reference="rplidar_link">
<sensor type="ray" name="rplidar">
    <pose>0 0 0 0 0 0</pose>
    <visualize>true</visualize>
    <update_rate>60</update_rate>
    <ray>
    <scan>
        <horizontal>
        <samples>360</samples>
        <resolution>1</resolution>
        <min_angle>0</min_angle>
        <max_angle>6.28319</max_angle> <!-- 2*PI -->
        </horizontal>
    </scan>
    <range>
        <min>0.4</min>
        <max>6.0</max>
        <resolution>0.01</resolution>
    </range>
    <noise>
        <type>gaussian</type>
        <mean>0.0</mean>
        <stddev>0.01</stddev>
    </noise>
    </ray>
    <plugin name="gazebo_ros_laser_controller" filename="libgazebo_ros_laser.so">
    <topicName>/scan</topicName>
    <frameName>rplidar_link</frameName>
    </plugin>
</sensor>
</gazebo>

<!-- REALSENSE -->



    <!-- PLUGIN -->
    <xacro:include filename="rovid_plugin.xacro"/>
        <!-- Motor plugin -->

    <xacro:include filename="$(find realsense2_description)/urdf/_l515.urdf.xacro" />
    <xacro:sensor_l515 name="camera_l515" topics_ns="camera" parent="base_link" use_nominal_extrinsics="true" publish_pointcloud="true" add_plug="false" use_mesh="true">
        <origin xyz="0.25 0 0.9" rpy="0 0 0" />
    </xacro:sensor_l515>  
    
    <xacro:rovid_diff_drive /> 

    <!-- Joints plugin -->
    <xacro:rovid_joints_state_publisher />


</robot>
