<?xml version="1.0" ?>
<!-- =================================================================================== -->
<!-- |    This document was autogenerated by xacro from robot.xacro                    | -->
<!-- |    EDITING THIS FILE BY HAND IS NOT RECOMMENDED                                 | -->
<!-- =================================================================================== -->
<robot name="my_robot">
  <link name="base_link">
    <visual>
      <origin rpy="1.57075 0.0 0.0" xyz="0.0 0.0 0.0"/>
      <geometry>
        <cylinder length="0.62" radius="0.02"/>
      </geometry>
    </visual>
  </link>
  <!-- Material Definitions -->
  <material name="black">
    <color rgba="0.0 0.0 0.0 1.0"/>
  </material>
  <material name="white">
    <color rgba="1.0 1.0 1.0 1.0"/>
  </material>
  <material name="blue">
    <color rgba="0.0 0.0 1.0 1.0"/>
  </material>
  <material name="green">
    <color rgba="0.0 1.0 0.0 1.0"/>
  </material>
  <material name="roda">
    <color rgba="0.4 0.4313 0.40784 1.0"/>
  </material>
  <!-- Link Definitions -->
  <link name="body_link">
    <visual>
      <origin rpy="0.0 0.0 0.0" xyz="0.0 0.0 0.0875"/>
      <geometry>
        <mesh filename="package://my_robot_description/meshes/UpperBody1v13.stl" scale="1 1 1"/>
      </geometry>
      <material name="black"/>
    </visual>
    <collision>
      <origin rpy="0.0 0.0 0.0" xyz="0.0 0.0 0.0875"/>
      <geometry>
        <mesh filename="package://my_robot_description/meshes/UpperBody1v13.stl" scale="1 1 1"/>
      </geometry>
    </collision>
    <inertial>
      <origin rpy="0.0 0.0 0.0" xyz="0.0 0.0 0.0875"/>
      <mass value="1.0"/>
      <inertia ixx="1" ixy="0" ixz="0" iyy="1" iyz="0" izz="1"/>
    </inertial>
  </link>
  <link name="right_wheel">
    <visual>
      <origin rpy="0.0 0.0 0" xyz="0.0 0 0"/>
      <geometry>
        <mesh filename="package://my_robot_description/meshes/wheel.stl" scale="1 1 1"/>
      </geometry>
      <material name="roda"/>
    </visual>
    <collision>
      <origin rpy="0.0 0.0 0" xyz="0.0 0 0"/>
      <geometry>
        <mesh filename="package://my_robot_description/meshes/wheel.stl" scale="1 1 1"/>
      </geometry>
    </collision>
    <inertial>
      <mass value="0.5"/>
      <origin rpy="0.0 0.0 0" xyz="0.0 0 0"/>
      <inertia ixx="0.001" ixy="0.0" ixz="0.0" iyy="0.001" iyz="0.0" izz="0.001"/>
    </inertial>
  </link>
  <link name="left_wheel">
    <visual>
      <origin rpy="0.0 0.0 0" xyz="0.0 0 0"/>
      <geometry>
        <mesh filename="package://my_robot_description/meshes/wheel.stl" scale="1 1 1"/>
      </geometry>
      <material name="roda"/>
    </visual>
    <collision>
      <origin rpy="0.0 0.0 0" xyz="0.0 0 0"/>
      <geometry>
        <mesh filename="package://my_robot_description/meshes/wheel.stl" scale="1 1 1"/>
      </geometry>
    </collision>
    <inertial>
      <mass value="0.5"/>
      <origin rpy="0.0 0.0 0" xyz="0.0 0 0"/>
      <inertia ixx="0.001" ixy="0.0" ixz="0.0" iyy="0.001" iyz="0.0" izz="0.001"/>
    </inertial>
  </link>
  <link name="small_wheel">
    <visual>
      <origin rpy="0.0 0.0 0" xyz="0.0 0 0"/>
      <geometry>
        <mesh filename="package://my_robot_description/meshes/small_wheel.stl" scale="1 1 1"/>
      </geometry>
      <material name="roda"/>
    </visual>
    <collision>
      <origin rpy="0.0 0.0 0" xyz="0.0 0 0"/>
      <geometry>
        <mesh filename="package://my_robot_description/meshes/small_wheel.stl" scale="1 1 1"/>
      </geometry>
    </collision>
    <inertial>
      <mass value="0.5"/>
      <origin rpy="0.0 0.0 0" xyz="0.0 0 0"/>
      <inertia ixx="0.001" ixy="0.0" ixz="0.0" iyy="0.001" iyz="0.0" izz="0.001"/>
    </inertial>
  </link>
  <joint name="body_link" type="fixed">
    <parent link="base_link"/>
    <child link="body_link"/>
    <origin rpy="0.0 0.0 0.0" xyz="0.0 0.0 0.0"/>
  </joint>
  <joint name="right_wheel_joint" type="revolute">
    <parent link="body_link"/>
    <child link="right_wheel"/>
    <origin rpy="0.0 0.0 0" xyz="0.0 0.16 0.0875"/>
    <axis xyz="0 1 0"/>
    <limit effort="10" lower="-3.14" upper="3.14" velocity="40"/>
  </joint>
  <joint name="left_wheel_jount" type="revolute">
    <parent link="body_link"/>
    <child link="left_wheel"/>
    <origin rpy="0.0 0.0 0" xyz="0.0 -0.16 0.0875"/>
    <axis xyz="0 1 0"/>
    <limit effort="10" lower="-3.14" upper="3.14" velocity="40"/>
  </joint>
  <joint name="small_wheel_joint" type="revolute">
    <parent link="body_link"/>
    <child link="small_wheel"/>
    <origin rpy="0.0 0.0 0" xyz="0.17 0.0 0.02"/>
    <axis xyz="0 1 0"/>
    <limit effort="10" lower="-3.14" upper="3.14" velocity="40"/>
  </joint>
</robot>
